Workbook
Name Slicer_Project_Health: #N/A

Sheet Projects
A1: Project_ID | B1: Project_Name | C1: City | D1: Client_ID | E1: Budget | F1: Start_Date | G1: End_Date | H1: Manager
A2: P001 | B2: SteelBuild Phase 1 | C2: Hyderabad | D2: C042 | E2: 360000000 | F2: 45826 | G2: 46311 | H2: Manager 5
A3: P002 | B3: SteelBuild Phase 2 | C3: Noida | D3: C006 | E3: 370000000 | F3: 45730 | G3: 46226 | H3: Manager 14
A4: P003 | B4: SteelBuild Phase 3 | C4: Noida | D4: C068 | E4: 370000000 | F4: 45845 | G4: 46383 | H4: Manager 19
A5: P004 | B5: SteelBuild Phase 4 | C5: Jaipur | D5: C011 | E5: 60000000 | F5: 45871 | G5: 46059 | H5: Manager 2
A6: P005 | B6: SteelBuild Phase 5 | C6: Pune | D6: C014 | E6: 290000000 | F6: 45692 | G6: 46198 | H6: Manager 15
A7: P006 | B7: SteelBuild Phase 6 | C7: Delhi | D7: C069 | E7: 200000000 | F7: 45800 | G7: 46005 | H7: Manager 16
A8: P007 | B8: SteelBuild Phase 7 | C8: Bengaluru | D8: C009 | E8: 370000000 | F8: 45725 | G8: 45906 | H8: Manager 18
A9: P008 | B9: SteelBuild Phase 8 | C9: Gurgaon | D9: C061 | E9: 210000000 | F9: 45681 | G9: 46198 | H9: Manager 3
A10: P009 | B10: SteelBuild Phase 9 | C10: Jaipur | D10: C027 | E10: 190000000 | F10: 45874 | G10: 46189 | H10: Manager 15
A11: P010 | B11: SteelBuild Phase 10 | C11: Gurgaon | D11: C062 | E11: 230000000 | F11: 45784 | G11: 46159 | H11: Manager 2
A12: P011 | B12: SteelBuild Phase 11 | C12: Jaipur | D12: C010 | E12: 140000000 | F12: 45815 | G12: 46318 | H12: Manager 11
A13: P012 | B13: SteelBuild Phase 12 | C13: Lucknow | D13: C080 | E13: 130000000 | F13: 45723 | G13: 46236 | H13: Manager 1
... A86: P085 | B86: SteelBuild Phase 85 | C86: Jaipur | D86: C024 | E86: 200000000 | F86: 45708 | G86: 46112 | H86: Manager 8
A87: P086 | B87: SteelBuild Phase 86 | C87: Jaipur | D87: C042 | E87: 90000000 | F87: 45697 | G87: 46021 | H87: Manager 13 | L87: 90000000
A88: P087 | B88: SteelBuild Phase 87 | C88: Jaipur | D88: C013 | E88: 340000000 | F88: 45722 | G88: 46027 | H88: Manager 2
A89: P088 | B89: SteelBuild Phase 88 | C89: Bengaluru | D89: C030 | E89: 330000000 | F89: 45684 | G89: 45866 | H89: Manager 12
A90: P089 | B90: SteelBuild Phase 89 | C90: Jaipur | D90: C016 | E90: 80000000 | F90: 45668 | G90: 45998 | H90: Manager 7
A91: P090 | B91: SteelBuild Phase 90 | C91: Jaipur | D91: C010 | E91: 280000000 | F91: 45811 | G91: 46289 | H91: Manager 17
A92: P091 | B92: SteelBuild Phase 91 | C92: Bengaluru | D92: C078 | E92: 210000000 | F92: 45879 | G92: 46150 | H92: Manager 1
A93: P092 | B93: SteelBuild Phase 92 | C93: Pune | D93: C028 | E93: 70000000 | F93: 45685 | G93: 46191 | H93: Manager 12
A94: P093 | B94: SteelBuild Phase 93 | C94: Delhi | D94: C027 | E94: 210000000 | F94: 45745 | G94: 45997 | H94: Manager 2
A95: P094 | B95: SteelBuild Phase 94 | C95: Jaipur | D95: C002 | E95: 250000000 | F95: 45811 | G95: 46324 | H95: Manager 14
A96: P095 | B96: SteelBuild Phase 95 | C96: Noida | D96: C080 | E96: 240000000 | F96: 45831 | G96: 46201 | H96: Manager 3
A97: P096 | B97: SteelBuild Phase 96 | C97: Bengaluru | D97: C071 | E97: 350000000 | F97: 45710 | G97: 45906 | H97: Manager 3
A98: P097 | B98: SteelBuild Phase 97 | C98: Hyderabad | D98: C071 | E98: 140000000 | F98: 45762 | G98: 45993 | H98: Manager 18
A99: P098 | B99: SteelBuild Phase 98 | C99: Noida | D99: C051 | E99: 220000000 | F99: 45681 | G99: 46195 | H99: Manager 14
... A151: P150 | B151: SteelBuild Phase 150 | C151: Lucknow | D151: C007 | E151: 220000000 | F151: 45743 | G151: 46278 | H151: Manager 18

Sheet Clients
A1: Client_ID | B1: Client_Name | C1: Industry | D1: City
A2: C001 | B2: Client 1 | C2: Residential | D2: Noida
A3: C002 | B3: Client 2 | C3: Residential | D3: Delhi
A4: C003 | B4: Client 3 | C4: Commercial | D4: Gurgaon
A5: C004 | B5: Client 4 | C5: Residential | D5: Delhi
A6: C005 | B6: Client 5 | C6: Industrial | D6: Jaipur
A7: C006 | B7: Client 6 | C7: Commercial | D7: Gurgaon
A8: C007 | B8: Client 7 | C8: Residential | D8: Hyderabad
A9: C008 | B9: Client 8 | C9: Commercial | D9: Jaipur
A10: C009 | B10: Client 9 | C10: Commercial | D10: Hyderabad
A11: C010 | B11: Client 10 | C11: Commercial | D11: Gurgaon
A12: C011 | B12: Client 11 | C12: Commercial | D12: Delhi
... A81: C080 | B81: Client 80 | C81: Commercial | D81: Jaipur

Sheet Vendors
A1: Vendor_ID | B1: Vendor_Name | C1: Category | D1: City
A2: V001 | B2: Vendor 1 | C2: Civil | D2: Noida
A3: V002 | B3: Vendor 2 | C3: Steel | D3: Pune
A4: V003 | B4: Vendor 3 | C4: Paint | D4: Delhi
A5: V004 | B5: Vendor 4 | C5: Steel | D5: Delhi
A6: V005 | B6: Vendor 5 | C6: Paint | D6: Noida
A7: V006 | B7: Vendor 6 | C7: Paint | D7: Gurgaon
A8: V007 | B8: Vendor 7 | C8: Electrical | D8: Delhi
A9: V008 | B9: Vendor 8 | C9: Steel | D9: Jaipur
A10: V009 | B10: Vendor 9 | C10: Paint | D10: Hyderabad
A11: V010 | B11: Vendor 10 | C11: Cement | D11: Lucknow
A12: V011 | B12: Vendor 11 | C12: Electrical | D12: Pune
... A181: V180 | B181: Vendor 180 | C181: Paint | D181: Noida

Sheet Employees
A1: Employee_ID | B1: Employee_Name | C1: Department | D1: Designation | E1: Salary
A2: E0001 | B2: Employee 1 | C2: MIS | D2: Analyst | E2: 114880
A3: E0002 | B3: Employee 2 | C3: Planning | D3: Manager | E3: 63747
A4: E0003 | B4: Employee 3 | C4: MIS | D4: Executive | E4: 36196
A5: E0004 | B5: Employee 4 | C5: Planning | D5: Engineer | E5: 47252
A6: E0005 | B6: Employee 5 | C6: HR | D6: Executive | E6: 51578
A7: E0006 | B7: Employee 6 | C7: Finance | D7: Manager | E7: 50157
A8: E0007 | B8: Employee 7 | C8: Procurement | D8: Manager | E8: 103804
A9: E0008 | B9: Employee 8 | C9: Finance | D9: Analyst | E9: 107666
A10: E0009 | B10: Employee 9 | C10: MIS | D10: Supervisor | E10: 86537
A11: E0010 | B11: Employee 10 | C11: Procurement | D11: Supervisor | E11: 116438
A12: E0011 | B12: Employee 11 | C12: Operations | D12: Engineer | E12: 82306
A13: E0012 | B13: Employee 12 | C13: MIS | D13: Executive | E13: 99755
... A451: E0450 | B451: Employee 450 | C451: Planning | D451: Analyst | E451: 76054

Sheet Materials_Master
A1: Material_ID | B1: Material | C1: Unit
A2: M001 | B2: Steel | C2: Nos
A3: M002 | B3: Cement | C3: Ton
A4: M003 | B4: Sand | C4: MT
A5: M004 | B5: Bricks | C5: Ltr
A6: M005 | B6: Paint | C6: SqFt
A7: M006 | B7: Tiles | C7: Ton
A8: M007 | B8: Pipes | C8: Nos
A9: M008 | B9: Concrete | C9: MT

Sheet Material_Purchases
A1: Purchase_ID | B1: Project_ID | C1: Vendor_ID | D1: Material_ID | E1: Qty | F1: Unit_Cost | G1: Purchase_Date | H1: Revenue
A2: PUR00001 | B2: P018 | C2: V059 | D2: M002 | E2: 269 | F2: 3305.68 | G2: 46170 | H2: 889227.92
A3: PUR00002 | B3: P144 | C3: V147 | D3: M003 | E3: 476 | F3: 7044.69 | G3: 46089 | H3: 3353272.4
A4: PUR00003 | B4: P103 | C4: V160 | D4: M006 | E4: 226 | F4: 5548.05 | G4: 45752 | H4: 1253859.3
A5: PUR00004 | B5: P093 | C5: V094 | D5: M002 | E5: 163 | F5: 6616.93 | G5: 46182 | H5: 1078559.6
A6: PUR00005 | B6: P029 | C6: V076 | D6: M006 | E6: 336 | F6: 6573.41 | G6: 46179 | H6: 2208665.8
A7: PUR00006 | B7: P041 | C7: V075 | D7: M004 | E7: 269 | F7: 4063.85 | G7: 45850 | H7: 1093175.6
A8: PUR00007 | B8: P047 | C8: V162 | D8: M002 | E8: 31 | F8: 2857.81 | G8: 45701 | H8: 88592.11
A9: PUR00008 | B9: P106 | C9: V001 | D9: M005 | E9: 6 | F9: 5699.57 | G9: 45662 | H9: 34197.42
A10: PUR00009 | B10: P102 | C10: V026 | D10: M001 | E10: 432 | F10: 5361.45 | G10: 45859 | H10: 2316146.4
A11: PUR00010 | B11: P128 | C11: V142 | D11: M005 | E11: 394 | F11: 6975.55 | G11: 46184 | H11: 2748366.7
A12: PUR00011 | B12: P148 | C12: V106 | D12: M002 | E12: 102 | F12: 1205.56 | G12: 46188 | H12: 122967.12
A13: PUR00012 | B13: P028 | C13: V026 | D13: M002 | E13: 15 | F13: 1405.76 | G13: 46193 | H13: 21086.4
... A7478: PUR07500 | B7478: P116 | C7478: V053 | D7478: M003 | E7478: 365 | F7478: 3913.65 | G7478: 46124 | H7478: 1428482.2

Sheet Labour_Attendance
A1: Attendance_ID | B1: Employee_ID | C1: Project_ID | D1: Work_Date | E1: Hours
A2: AT00001 | B2: E0157 | C2: P043 | D2: 46003 | E2: 5
A3: AT00002 | B3: E0143 | C3: P104 | D3: 46031 | E3: 11
A4: AT00003 | B4: E0060 | C4: P137 | D4: 46091 | E4: 8
A5: AT00004 | B5: E0242 | C5: P006 | D5: 45875 | E5: 6
A6: AT00005 | B6: E0443 | C6: P143 | D6: 46080 | E6: 5
A7: AT00006 | B7: E0126 | C7: P118 | D7: 45770 | E7: 10
A8: AT00007 | B8: E0066 | C8: P043 | D8: 45839 | E8: 11
A9: AT00008 | B9: E0014 | C9: P099 | D9: 46182 | E9: 9
A10: AT00009 | B10: E0179 | C10: P031 | D10: 45944 | E10: 9
A11: AT00010 | B11: E0341 | C11: P048 | D11: 46000 | E11: 9
A12: AT00011 | B12: E0008 | C12: P099 | D12: 46086 | E12: 9
A13: AT00012 | B13: E0391 | C13: P124 | D13: 45793 | E13: 4
... A8001: AT08000 | B8001: E0207 | C8001: P132 | D8001: 46041 | E8001: 7

Sheet Equipment_Usage
A1: Usage_ID | B1: Project_ID | C1: Machine | D1: Hours | E1: Fuel_Cost
A2: U00001 | B2: P050 | C2: Mixer | D2: 4 | E2: 6884
A3: U00002 | B3: P146 | C3: Excavator | D3: 1 | E3: 10685
A4: U00003 | B4: P118 | C4: Crane | D4: 5 | E4: 5140
A5: U00004 | B5: P120 | C5: Excavator | D5: 12 | E5: 4448
A6: U00005 | B6: P133 | C6: Crane | D6: 7 | E6: 14764
A7: U00006 | B7: P037 | C7: Crane | D7: 1 | E7: 24665
A8: U00007 | B8: P126 | C8: Excavator | D8: 3 | E8: 10027
A9: U00008 | B9: P112 | C9: Excavator | D9: 3 | E9: 16889
A10: U00009 | B10: P080 | C10: Mixer | D10: 8 | E10: 1582
A11: U00010 | B11: P146 | C11: Mixer | D11: 2 | E11: 24925
A12: U00011 | B12: P107 | C12: Pump | D12: 4 | E12: 5957
A13: U00012 | B13: P036 | C13: Loader | D13: 11 | E13: 14706
... A2501: U02500 | B2501: P056 | C2501: Loader | D2501: 8 | E2501: 20566

Sheet Inventory
A1: Txn_ID | B1: Project_ID | C1: Material_ID | D1: Movement | E1: Qty | F1: Txn_Date
A2: T00001 | B2: P093 | C2: M008 | D2: IN | E2: 132 | F2: 45798
A3: T00002 | B3: P012 | C3: M008 | D3: OUT | E3: 122 | F3: 45797
A4: T00003 | B4: P029 | C4: M005 | D4: IN | E4: 100 | F4: 45860
A5: T00004 | B5: P107 | C5: M001 | D5: IN | E5: 74 | F5: 45727
A6: T00005 | B6: P118 | C6: M007 | D6: IN | E6: 244 | F6: 45972
A7: T00006 | B7: P141 | C7: M006 | D7: IN | E7: 69 | F7: 45757
A8: T00007 | B8: P024 | C8: M004 | D8: IN | E8: 248 | F8: 46046
A9: T00008 | B9: P018 | C9: M005 | D9: IN | E9: 71 | F9: 45671
A10: T00009 | B10: P079 | C10: M006 | D10: IN | E10: 259 | F10: 45670
A11: T00010 | B11: P049 | C11: M003 | D11: OUT | E11: 15 | F11: 46013
A12: T00011 | B12: P124 | C12: M004 | D12: IN | E12: 213 | F12: 45689
A13: T00012 | B13: P011 | C13: M007 | D13: IN | E13: 203 | F13: 45983
... A2001: T02000 | B2001: P133 | C2001: M005 | D2001: OUT | E2001: 188 | F2001: 46090

Sheet Daily_Expenses
A1: Expense_ID | B1: Project_ID | C1: Expense_Type | D1: Amount | E1: Date
A2: EX00001 | B2: P123 | C2: Transport | D2: 108894 | E2: 45769
A3: EX00002 | B3: P087 | C3: Transport | D3: 90796 | E3: 46043
A4: EX00003 | B4: P109 | C4: Transport | D4: 196506 | E4: 45717
A5: EX00004 | B5: P123 | C5: Utilities | D5: 26386 | E5: 45795
A6: EX00005 | B6: P044 | C6: Safety | D6: 66309 | E6: 46038
A7: EX00006 | B7: P071 | C7: Misc | D7: 189729 | E7: 45756
A8: EX00007 | B8: P150 | C8: Utilities | D8: 168119 | E8: 46124
A9: EX00008 | B9: P071 | C9: Transport | D9: 167060 | E9: 45788
A10: EX00009 | B10: P117 | C10: Safety | D10: 45884 | E10: 45971
A11: EX00010 | B11: P010 | C11: Safety | D11: 52655 | E11: 46155
A12: EX00011 | B12: P017 | C12: Utilities | D12: 111931 | E12: 45963
A13: EX00012 | B13: P113 | C13: Utilities | D13: 73457 | E13: 46168
... A3001: EX03000 | B3001: P100 | C3001: Utilities | D3001: 145963 | E3001: 45939

Sheet Project_Progress
A1: Project_ID | B1: Report_Date | C1: Planned_% | D1: Actual_% | E1: Delay_Days | F1: Completion percent
A2: P001 | B2: 45781 | C2: 49 | D2: 34 | E2: 15 | F2: =Progress_Table[[#This Row],[Actual_%]]*100/Progress_Table[[#This Row],[Planned_%]] -> 69.387755
A3: P001 | B3: 45763 | C3: 100 | D3: 85 | E3: 15 | F3: =Progress_Table[[#This Row],[Actual_%]]*100/Progress_Table[[#This Row],[Planned_%]] -> 85
A4: P001 | B4: 45921 | C4: 89 | D4: 91 | E4: 0 | F4: =Progress_Table[[#This Row],[Actual_%]]*100/Progress_Table[[#This Row],[Planned_%]] -> 102.24719
A5: P001 | B5: 45718 | C5: 38 | D5: 28 | E5: 10 | F5: =Progress_Table[[#This Row],[Actual_%]]*100/Progress_Table[[#This Row],[Planned_%]] -> 73.684211
A6: P001 | B6: 46051 | C6: 66 | D6: 59 | E6: 7 | F6: =Progress_Table[[#This Row],[Actual_%]]*100/Progress_Table[[#This Row],[Planned_%]] -> 89.393939
A7: P001 | B7: 45956 | C7: 45 | D7: 40 | E7: 5 | F7: =Progress_Table[[#This Row],[Actual_%]]*100/Progress_Table[[#This Row],[Planned_%]] -> 88.888889
A8: P001 | B8: 45984 | C8: 38 | D8: 19 | E8: 19 | F8: =Progress_Table[[#This Row],[Actual_%]]*100/Progress_Table[[#This Row],[Planned_%]] -> 50
A9: P001 | B9: 45833 | C9: 64 | D9: 45 | E9: 19 | F9: =Progress_Table[[#This Row],[Actual_%]]*100/Progress_Table[[#This Row],[Planned_%]] -> 70.3125
A10: P002 | B10: 46193 | C10: 61 | D10: 66 | E10: 0 | F10: =Progress_Table[[#This Row],[Actual_%]]*100/Progress_Table[[#This Row],[Planned_%]] -> 108.19672
A11: P002 | B11: 46176 | C11: 25 | D11: 27 | E11: 0 | F11: =Progress_Table[[#This Row],[Actual_%]]*100/Progress_Table[[#This Row],[Planned_%]] -> 108
A12: P002 | B12: 46049 | C12: 5 | D12: 0 | E12: 5 | F12: =Progress_Table[[#This Row],[Actual_%]]*100/Progress_Table[[#This Row],[Planned_%]] -> 0
A13: P002 | B13: 45713 | C13: 74 | D13: 55 | E13: 19 | F13: =Progress_Table[[#This Row],[Actual_%]]*100/Progress_Table[[#This Row],[Planned_%]] -> 74.324324
... A1201: P150 | B1201: 45784 | C1201: 67 | D1201: 59 | E1201: 8 | F1201: =Progress_Table[[#This Row],[Actual_%]]*100/Progress_Table[[#This Row],[Planned_%]] -> 88.059701

Sheet Client_Payments
A1: Payment_ID | B1: Project_ID | C1: Client_ID | D1: Amount | E1: Status | F1: Payment_Date
A2: PAY0001 | B2: P086 | C2: C021 | D2: 1134380 | E2: Pending | F2: 45845
A3: PAY0002 | B3: P016 | C3: C040 | D3: 1925231 | E3: Pending | F3: 45817
A4: PAY0003 | B4: P111 | C4: C076 | D4: 3477278 | E4: Paid | F4: 45805
A5: PAY0004 | B5: P139 | C5: C080 | D5: 4906833 | E5: Partial | F5: 45741
A6: PAY0005 | B6: P117 | C6: C075 | D6: 3891628 | E6: Pending | F6: 45925
A7: PAY0006 | B7: P101 | C7: C044 | D7: 2725782 | E7: Paid | F7: 45885
A8: PAY0007 | B8: P068 | C8: C048 | D8: 1670778 | E8: Pending | F8: 45824
A9: PAY0008 | B9: P128 | C9: C026 | D9: 1557459 | E9: Paid | F9: 46184
A10: PAY0009 | B10: P093 | C10: C058 | D10: 2148131 | E10: Partial | F10: 46082
A11: PAY0010 | B11: P146 | C11: C026 | D11: 917373 | E11: Paid | F11: 46003
A12: PAY0011 | B12: P084 | C12: C011 | D12: 1831394 | E12: Partial | F12: 45716
A13: PAY0012 | B13: P093 | C13: C018 | D13: 3576206 | E13: Paid | F13: 46131
... A701: PAY0700 | B701: P143 | C701: C045 | D701: 1594897 | E701: Pending | F701: 46046

Sheet Safety_Incidents
A1: Incident_ID | B1: Project_ID | C1: Severity | D1: Lost_Time_Days | E1: Date
A2: S0001 | B2: P067 | C2: Medium | D2: 17 | E2: 46020
A3: S0002 | B3: P032 | C3: High | D3: 15 | E3: 45942
A4: S0003 | B4: P102 | C4: High | D4: 10 | E4: 46079
A5: S0004 | B5: P098 | C5: Low | D5: 8 | E5: 45775
A6: S0005 | B6: P036 | C6: Low | D6: 2 | E6: 45844
A7: S0006 | B7: P097 | C7: Low | D7: 20 | E7: 45969
A8: S0007 | B8: P044 | C8: High | D8: 8 | E8: 45858
A9: S0008 | B9: P061 | C9: Low | D9: 0 | E9: 45740
A10: S0009 | B10: P048 | C10: High | D10: 19 | E10: 45674
A11: S0010 | B11: P087 | C11: High | D11: 19 | E11: 45931
A12: S0011 | B12: P054 | C12: Medium | D12: 7 | E12: 45685
A13: S0012 | B13: P067 | C13: Low | D13: 7 | E13: 46061
... A121: S0120 | B121: P038 | C121: Low | D121: 11 | E121: 45982

Sheet Data_Dictionary
A1: Sheet Name | B1: Column Name | C1: Data Type | D1: Description | E1: Example | F1: Business Rule | G1: Nullable
A2: Projects | B2: Project_ID | C2: Text | D2: Unique identifier assigned to each construction project. | E2: P001 | F2: Must be unique and cannot be blank. | G2: No
A3: Projects | B3: Project_Name | C3: Text | D3: Official name of the project. | E3: SteelBuild Phase 1 | F3: Cannot be blank. | G3: No
A4: Projects | B4: City | C4: Text | D4: City where the project is executed. | E4: Delhi | F4: Must belong to approved city list. | G4: No
A5: Projects | B5: Client_ID | C5: Text | D5: Client responsible for the project. | E5: C001 | F5: Must exist in Clients table. | G5: No
A6: Projects | B6: Budget | C6: Currency | D6: Approved project budget in INR. | E6: 250000000 | F6: Must be > 0. | G6: No
A7: Projects | B7: Start_Date | C7: Date | D7: Project start date. | E7: 01-Jan-2025 | F7: Must be before End_Date. | G7: No
A8: Projects | B8: End_Date | C8: Date | D8: Project completion date. | E8: 30-Dec-2025 | F8: Must be after Start_Date. | G8: No
A9: Projects | B9: Manager | C9: Text | D9: Project manager. | E9: Manager 1 | F9: Valid manager name. | G9: Yes
A10: Clients | B10: Client_ID | C10: Text | D10: Unique client identifier. | E10: C001 | F10: Must be unique. | G10: No
A11: Clients | B11: Client_Name | C11: Text | D11: Client organization name. | E11: Client 1 | F11: Cannot be blank. | G11: No
A12: Clients | B12: Industry | C12: Text | D12: Industry sector. | E12: Commercial | F12: Valid industry. | G12: No
A13: Clients | B13: City | C13: Text | D13: Client city. | E13: Delhi | F13: Cannot be blank. | G13: No
A14: Vendors | B14: Vendor_ID | C14: Text | D14: Unique vendor identifier. | E14: V001 | F14: Must be unique. | G14: No
A15: Vendors | B15: Vendor_Name | C15: Text | D15: Supplier name. | E15: Vendor 1 | F15: Cannot be blank. | G15: No
A16: Vendors | B16: Category | C16: Text | D16: Vendor category. | E16: Steel | F16: Valid category. | G16: No
A17: Vendors | B17: City | C17: Text | D17: Vendor city. | E17: Pune | F17: Optional. | G17: Yes
A18: Employees | B18: Employee_ID | C18: Text | D18: Unique employee identifier. | E18: E0001 | F18: Must be unique. | G18: No
... A21: Employees | B21: Designation | C21: Text | D21: Employee designation. | E21: Analyst | F21: Cannot be blank. | G21: No
A22: Employees | B22: Salary | C22: Currency | D22: Monthly salary. | E22: 65000 | F22: Must be >0. | G22: No
A23: Materials_Master | B23: Material_ID | C23: Text | D23: Unique material identifier. | E23: M001 | F23: Must be unique. | G23: No
A24: Materials_Master | B24: Material | C24: Text | D24: Material name. | E24: Steel | F24: Cannot be blank. | G24: No
A25: Materials_Master | B25: Unit | C25: Text | D25: Measurement unit. | E25: MT | F25: Valid unit. | G25: No
A26: Material_Purchases | B26: Purchase_ID | C26: Text | D26: Purchase transaction ID. | E26: PUR00001 | F26: Must be unique. | G26: No
A27: Material_Purchases | B27: Project_ID | C27: Text | D27: Project reference. | E27: P001 | F27: Must exist in Projects. | G27: No
A28: Material_Purchases | B28: Vendor_ID | C28: Text | D28: Vendor reference. | E28: V001 | F28: Must exist in Vendors. | G28: No
A29: Material_Purchases | B29: Material_ID | C29: Text | D29: Material reference. | E29: M001 | F29: Must exist in Materials_Master. | G29: No
A30: Material_Purchases | B30: Qty | C30: Number | D30: Purchased quantity. | E30: 250 | F30: Must be >0. | G30: No
A31: Material_Purchases | B31: Unit_Cost | C31: Currency | D31: Cost per unit. | E31: 4800 | F31: Must be >0. | G31: No
A32: Material_Purchases | B32: Purchase_Date | C32: Date | D32: Purchase date. | E32: 12-Feb-2025 | F32: Valid date. | G32: No
A33: Material_Purchases | B33: Revenue | C33: Currency | D33: cost per unit * purchased quantity | E33: 889227.92 | F33: Must be >0. | G33: No
A34: Labour_Attendance | B34: Attendance_ID | C34: Text | D34: Attendance transaction ID. | E34: AT00001 | F34: Must be unique. | G34: No
A35: Labour_Attendance | B35: Employee_ID | C35: Text | D35: Employee reference. | E35: E0010 | F35: Must exist in Employees. | G35: No
A36: Labour_Attendance | B36: Project_ID | C36: Text | D36: Project reference. | E36: P001 | F36: Must exist in Projects. | G36: No
A37: Labour_Attendance | B37: Work_Date | C37: Date | D37: Attendance date. | E37: 05-Mar-2025 | F37: Valid date. | G37: No
A38: Labour_Attendance | B38: Hours | C38: Number | D38: Hours worked. | E38: 8 | F38: Must be >0. | G38: No
A39: Equipment_Usage | B39: Usage_ID | C39: Text | D39: Equipment usage ID. | E39: U00001 | F39: Must be unique. | G39: No
A40: Equipment_Usage | B40: Project_ID | C40: Text | D40: Project reference. | E40: P001 | F40: Must exist in Projects. | G40: No
A41: Equipment_Usage | B41: Machine | C41: Text | D41: Machine used. | E41: Crane | F41: Cannot be blank. | G41: No
A42: Equipment_Usage | B42: Hours | C42: Number | D42: Machine hours. | E42: 6 | F42: Must be >0. | G42: No
...

Sheet Analysis
A1: Total Client Payments | B1: =SUMIFS(Client_Payment_Table[Amount],Client_Payment_Table[Status],"Paid") -> 556543428
A3: Total Material Purchase Cost | B3: =SUM(Material_Purchase_Table[Revenue]) -> 7.5787405e+09
A5: Total Daily Expenses | B5: =SUM(Daily_Expenses_Table[Amount]) -> 302208828
A7: Total Equipment Usage Cost | B7: =SUM(Equipment_Table[Fuel_Cost]) -> 32421097
A9: Total Number of Projects | B9: =COUNTA(Project_Table[Project_ID]) -> 150

Sheet Project_Analysis
A1: Project ID | B1: Project_Name | C1: Budget | D1: Paid_Client Payments | E1: Material Cost | F1: Daily Expenses | G1: Equipment Cost | H1: Total_Actual_Cost | I1: Budget_Variance | J1: Budget_Utilization_% | K1: Project_Health | L1: Material Cost_% | M1: Daily Expenses_% | N1: Equipment Cost_% | O1: Major_Cost_driver | R1: TOTAL PROJECTS | T1: TOTAL BUDGET | V1: ACTUAL COST | X1: BUDGET UTILIZATION | Z1: CRITICAL PROJECTS | AB1: ATTENTION PROJECTS
A2: P001 | B2: =INDEX(Project_Table[],MATCH(Project_Analysis!$A2,Project_Table[Project_ID],0),MATCH(Project_Analysis!B$1,Project_Table[#Headers],0)) -> SteelBuild Phase 1 | C2: =INDEX(Project_Table[],MATCH(Project_Analysis!$A2,Project_Table[Project_ID],0),MATCH(Project_Analysis!C$1,Project_Table[#Headers],0)) -> 360000000 | D2: =SUMIFS(Client_Payment_Table[Amount],Client_Payment_Table[Status],"Paid",Client_Payment_Table[Project_ID],Project_Analysis!$A2) -> 0 | E2: =SUMIFS(Material_Purchase_Table[Revenue],Material_Purchase_Table[Project_ID],Project_Analysis!$A2) -> 60296675 | F2: =SUMIFS(Daily_Expenses_Table[Amount],Daily_Expenses_Table[Project_ID],Project_Analysis!$A2) -> 2048551 | G2: =SUMIFS(Equipment_Table[Fuel_Cost],Equipment_Table[Project_ID],Project_Analysis!$A2) -> 142608 | H2: =E2+F2+G2 -> 62487834 | I2: =C2-H2 -> 2.9751217e+08 | J2: =H2*100/C2 -> 17.357732 | K2: =IF(J2>100,"Critical",IF(AND(J2>=80,J2<=100),"Attention","Healthy")) -> Healthy | L2: =E2*100/H2 -> 96.493463 | M2: =F2*100/H2 -> 3.2783197 | N2: =G2*100/H2 -> 0.22821722 | O2: =IF(L2=MAX(L2,M2,N2),"Material",IF(M2=MAX(L2,M2,N2),"Daily Expense","Equipment")) -> Material | R2: =COUNTA(Pivot_Analysis_Table[Project ID]) -> 150 | T2: =SUM(Pivot_Analysis_Table[Budget])/10000000 -> 3324 | V2: =SUM(Pivot_Analysis_Table[Total_Actual_Cost])/10000000 -> 791.33705 | X2: =SUM(Pivot_Analysis_Table[Total_Actual_Cost])/SUM(Pivot_Analysis_Table[Budget]) -> 0.2380677 | Z2: =COUNTIF(Pivot_Analysis_Table[Project_Health],"Critical") -> 2 | AB2: =COUNTIF(Pivot_Analysis_Table[Project_Health],"Attention") -> 4
A3: P002 | B3: =INDEX(Project_Table[],MATCH(Project_Analysis!$A3,Project_Table[Project_ID],0),MATCH(Project_Analysis!B$1,Project_Table[#Headers],0)) -> SteelBuild Phase 2 | C3: =INDEX(Project_Table[],MATCH(Project_Analysis!$A3,Project_Table[Project_ID],0),MATCH(Project_Analysis!C$1,Project_Table[#Headers],0)) -> 370000000 | D3: =SUMIFS(Client_Payment_Table[Amount],Client_Payment_Table[Status],"Paid",Client_Payment_Table[Project_ID],Project_Analysis!$A3) -> 4824209 | E3: =SUMIFS(Material_Purchase_Table[Revenue],Material_Purchase_Table[Project_ID],Project_Analysis!$A3) -> 29722418 | F3: =SUMIFS(Daily_Expenses_Table[Amount],Daily_Expenses_Table[Project_ID],Project_Analysis!$A3) -> 1852279 | G3: =SUMIFS(Equipment_Table[Fuel_Cost],Equipment_Table[Project_ID],Project_Analysis!$A3) -> 184168 | H3: =E3+F3+G3 -> 31758865 | I3: =C3-H3 -> 3.3824114e+08 | J3: =H3*100/C3 -> 8.583477 | K3: =IF(J3>100,"Critical",IF(AND(J3>=80,J3<=100),"Attention","Healthy")) -> Healthy | L3: =E3*100/H3 -> 93.587784 | M3: =F3*100/H3 -> 5.8323212 | N3: =G3*100/H3 -> 0.57989478 | O3: =IF(L3=MAX(L3,M3,N3),"Material",IF(M3=MAX(L3,M3,N3),"Daily Expense","Equipment")) -> Material
A4: P003 | B4: =INDEX(Project_Table[],MATCH(Project_Analysis!$A4,Project_Table[Project_ID],0),MATCH(Project_Analysis!B$1,Project_Table[#Headers],0)) -> SteelBuild Phase 3 | C4: =INDEX(Project_Table[],MATCH(Project_Analysis!$A4,Project_Table[Project_ID],0),MATCH(Project_Analysis!C$1,Project_Table[#Headers],0)) -> 370000000 | D4: =SUMIFS(Client_Payment_Table[Amount],Client_Payment_Table[Status],"Paid",Client_Payment_Table[Project_ID],Project_Analysis!$A4) -> 1251371 | E4: =SUMIFS(Material_Purchase_Table[Revenue],Material_Purchase_Table[Project_ID],Project_Analysis!$A4) -> 52240338 | F4: =SUMIFS(Daily_Expenses_Table[Amount],Daily_Expenses_Table[Project_ID],Project_Analysis!$A4) -> 2319200 | G4: =SUMIFS(Equipment_Table[Fuel_Cost],Equipment_Table[Project_ID],Project_Analysis!$A4) -> 256668 | H4: =E4+F4+G4 -> 54816206 | I4: =C4-H4 -> 3.1518379e+08 | J4: =H4*100/C4 -> 14.815191 | K4: =IF(J4>100,"Critical",IF(AND(J4>=80,J4<=100),"Attention","Healthy")) -> Healthy | L4: =E4*100/H4 -> 95.300901 | M4: =F4*100/H4 -> 4.2308656 | N4: =G4*100/H4 -> 0.46823379 | O4: =IF(L4=MAX(L4,M4,N4),"Material",IF(M4=MAX(L4,M4,N4),"Daily Expense","Equipment")) -> Material
A5: P004 | B5: =INDEX(Project_Table[],MATCH(Project_Analysis!$A5,Project_Table[Project_ID],0),MATCH(Project_Analysis!B$1,Project_Table[#Headers],0)) -> SteelBuild Phase 4 | C5: =INDEX(Project_Table[],MATCH(Project_Analysis!$A5,Project_Table[Project_ID],0),MATCH(Project_Analysis!C$1,Project_Table[#Headers],0)) -> 60000000 | D5: =SUMIFS(Client_Payment_Table[Amount],Client_Payment_Table[Status],"Paid",Client_Payment_Table[Project_ID],Project_Analysis!$A5) -> 0 | E5: =SUMIFS(Material_Purchase_Table[Revenue],Material_Purchase_Table[Project_ID],Project_Analysis!$A5) -> 50972040 | F5: =SUMIFS(Daily_Expenses_Table[Amount],Daily_Expenses_Table[Project_ID],Project_Analysis!$A5) -> 1130124 | G5: =SUMIFS(Equipment_Table[Fuel_Cost],Equipment_Table[Project_ID],Project_Analysis!$A5) -> 235125 | H5: =E5+F5+G5 -> 52337289 | I5: =C5-H5 -> 7662711.2 | J5: =H5*100/C5 -> 87.228815 | K5: =IF(J5>100,"Critical",IF(AND(J5>=80,J5<=100),"Attention","Healthy")) -> Attention | L5: =E5*100/H5 -> 97.391441 | M5: =F5*100/H5 -> 2.1593094 | N5: =G5*100/H5 -> 0.44924948 | O5: =IF(L5=MAX(L5,M5,N5),"Material",IF(M5=MAX(L5,M5,N5),"Daily Expense","Equipment")) -> Material
A6: P005 | B6: =INDEX(Project_Table[],MATCH(Project_Analysis!$A6,Project_Table[Project_ID],0),MATCH(Project_Analysis!B$1,Project_Table[#Headers],0)) -> SteelBuild Phase 5 | C6: =INDEX(Project_Table[],MATCH(Project_Analysis!$A6,Project_Table[Project_ID],0),MATCH(Project_Analysis!C$1,Project_Table[#Headers],0)) -> 290000000 | D6: =SUMIFS(Client_Payment_Table[Amount],Client_Payment_Table[Status],"Paid",Client_Payment_Table[Project_ID],Project_Analysis!$A6) -> 0 | E6: =SUMIFS(Material_Purchase_Table[Revenue],Material_Purchase_Table[Project_ID],Project_Analysis!$A6) -> 42512679 | F6: =SUMIFS(Daily_Expenses_Table[Amount],Daily_Expenses_Table[Project_ID],Project_Analysis!$A6) -> 1853335 | G6: =SUMIFS(Equipment_Table[Fuel_Cost],Equipment_Table[Project_ID],Project_Analysis!$A6) -> 271324 | H6: =E6+F6+G6 -> 44637338 | I6: =C6-H6 -> 2.4536266e+08 | J6: =H6*100/C6 -> 15.392186 | K6: =IF(J6>100,"Critical",IF(AND(J6>=80,J6<=100),"Attention","Healthy")) -> Healthy | L6: =E6*100/H6 -> 95.240175 | M6: =F6*100/H6 -> 4.1519837 | N6: =G6*100/H6 -> 0.6078409 | O6: =IF(L6=MAX(L6,M6,N6),"Material",IF(M6=MAX(L6,M6,N6),"Daily Expense","Equipment")) -> Material
A7: P006 | B7: =INDEX(Project_Table[],MATCH(Project_Analysis!$A7,Project_Table[Project_ID],0),MATCH(Project_Analysis!B$1,Project_Table[#Headers],0)) -> SteelBuild Phase 6 | C7: =INDEX(Project_Table[],MATCH(Project_Analysis!$A7,Project_Table[Project_ID],0),MATCH(Project_Analysis!C$1,Project_Table[#Headers],0)) -> 200000000 | D7: =SUMIFS(Client_Payment_Table[Amount],Client_Payment_Table[Status],"Paid",Client_Payment_Table[Project_ID],Project_Analysis!$A7) -> 4445454 | E7: =SUMIFS(Material_Purchase_Table[Revenue],Material_Purchase_Table[Project_ID],Project_Analysis!$A7) -> 54268048 | F7: =SUMIFS(Daily_Expenses_Table[Amount],Daily_Expenses_Table[Project_ID],Project_Analysis!$A7) -> 1381637 | G7: =SUMIFS(Equipment_Table[Fuel_Cost],Equipment_Table[Project_ID],Project_Analysis!$A7) -> 219308 | H7: =E7+F7+G7 -> 55868993 | I7: =C7-H7 -> 1.4413101e+08 | J7: =H7*100/C7 -> 27.934496 | K7: =IF(J7>100,"Critical",IF(AND(J7>=80,J7<=100),"Attention","Healthy")) -> Healthy | L7: =E7*100/H7 -> 97.134466 | M7: =F7*100/H7 -> 2.4729943 | N7: =G7*100/H7 -> 0.39253974 | O7: =IF(L7=MAX(L7,M7,N7),"Material",IF(M7=MAX(L7,M7,N7),"Daily Expense","Equipment")) -> Material
A8: P007 | B8: =INDEX(Project_Table[],MATCH(Project_Analysis!$A8,Project_Table[Project_ID],0),MATCH(Project_Analysis!B$1,Project_Table[#Headers],0)) -> SteelBuild Phase 7 | C8: =INDEX(Project_Table[],MATCH(Project_Analysis!$A8,Project_Table[Project_ID],0),MATCH(Project_Analysis!C$1,Project_Table[#Headers],0)) -> 370000000 | D8: =SUMIFS(Client_Payment_Table[Amount],Client_Payment_Table[Status],"Paid",Client_Payment_Table[Project_ID],Project_Analysis!$A8) -> 2955370 | E8: =SUMIFS(Material_Purchase_Table[Revenue],Material_Purchase_Table[Project_ID],Project_Analysis!$A8) -> 54206134 | F8: =SUMIFS(Daily_Expenses_Table[Amount],Daily_Expenses_Table[Project_ID],Project_Analysis!$A8) -> 1343419 | G8: =SUMIFS(Equipment_Table[Fuel_Cost],Equipment_Table[Project_ID],Project_Analysis!$A8) -> 204407 | H8: =E8+F8+G8 -> 55753960 | I8: =C8-H8 -> 3.1424604e+08 | J8: =H8*100/C8 -> 15.068638 | K8: =IF(J8>100,"Critical",IF(AND(J8>=80,J8<=100),"Attention","Healthy")) -> Healthy | L8: =E8*100/H8 -> 97.223828 | M8: =F8*100/H8 -> 2.409549 | N8: =G8*100/H8 -> 0.36662329 | O8: =IF(L8=MAX(L8,M8,N8),"Material",IF(M8=MAX(L8,M8,N8),"Daily Expense","Equipment")) -> Material
A9: P008 | B9: =INDEX(Project_Table[],MATCH(Project_Analysis!$A9,Project_Table[Project_ID],0),MATCH(Project_Analysis!B$1,Project_Table[#Headers],0)) -> SteelBuild Phase 8 | C9: =INDEX(Project_Table[],MATCH(Project_Analysis!$A9,Project_Table[Project_ID],0),MATCH(Project_Analysis!C$1,Project_Table[#Headers],0)) -> 210000000 | D9: =SUMIFS(Client_Payment_Table[Amount],Client_Payment_Table[Status],"Paid",Client_Payment_Table[Project_ID],Project_Analysis!$A9) -> 8880203 | E9: =SUMIFS(Material_Purchase_Table[Revenue],Material_Purchase_Table[Project_ID],Project_Analysis!$A9) -> 48648169 | F9: =SUMIFS(Daily_Expenses_Table[Amount],Daily_Expenses_Table[Project_ID],Project_Analysis!$A9) -> 2304572 | G9: =SUMIFS(Equipment_Table[Fuel_Cost],Equipment_Table[Project_ID],Project_Analysis!$A9) -> 237659 | H9: =E9+F9+G9 -> 51190400 | I9: =C9-H9 -> 1.588096e+08 | J9: =H9*100/C9 -> 24.376381 | K9: =IF(J9>100,"Critical",IF(AND(J9>=80,J9<=100),"Attention","Healthy")) -> Healthy | L9: =E9*100/H9 -> 95.033774 | M9: =F9*100/H9 -> 4.5019613 | N9: =G9*100/H9 -> 0.46426479 | O9: =IF(L9=MAX(L9,M9,N9),"Material",IF(M9=MAX(L9,M9,N9),"Daily Expense","Equipment")) -> Material
A10: P009 | B10: =INDEX(Project_Table[],MATCH(Project_Analysis!$A10,Project_Table[Project_ID],0),MATCH(Project_Analysis!B$1,Project_Table[#Headers],0)) -> SteelBuild Phase 9 | C10: =INDEX(Project_Table[],MATCH(Project_Analysis!$A10,Project_Table[Project_ID],0),MATCH(Project_Analysis!C$1,Project_Table[#Headers],0)) -> 190000000 | D10: =SUMIFS(Client_Payment_Table[Amount],Client_Payment_Table[Status],"Paid",Client_Payment_Table[Project_ID],Project_Analysis!$A10) -> 0 | E10: =SUMIFS(Material_Purchase_Table[Revenue],Material_Purchase_Table[Project_ID],Project_Analysis!$A10) -> 52321523 | F10: =SUMIFS(Daily_Expenses_Table[Amount],Daily_Expenses_Table[Project_ID],Project_Analysis!$A10) -> 1834980 | G10: =SUMIFS(Equipment_Table[Fuel_Cost],Equipment_Table[Project_ID],Project_Analysis!$A10) -> 232058 | H10: =E10+F10+G10 -> 54388561 | I10: =C10-H10 -> 1.3561144e+08 | J10: =H10*100/C10 -> 28.625559 | K10: =IF(J10>100,"Critical",IF(AND(J10>=80,J10<=100),"Attention","Healthy")) -> Healthy | L10: =E10*100/H10 -> 96.199499 | M10: =F10*100/H10 -> 3.3738344 | N10: =G10*100/H10 -> 0.42666692 | O10: =IF(L10=MAX(L10,M10,N10),"Material",IF(M10=MAX(L10,M10,N10),"Daily Expense","Equipment")) -> Material
A11: P010 | B11: =INDEX(Project_Table[],MATCH(Project_Analysis!$A11,Project_Table[Project_ID],0),MATCH(Project_Analysis!B$1,Project_Table[#Headers],0)) -> SteelBuild Phase 10 | C11: =INDEX(Project_Table[],MATCH(Project_Analysis!$A11,Project_Table[Project_ID],0),MATCH(Project_Analysis!C$1,Project_Table[#Headers],0)) -> 230000000 | D11: =SUMIFS(Client_Payment_Table[Amount],Client_Payment_Table[Status],"Paid",Client_Payment_Table[Project_ID],Project_Analysis!$A11) -> 0 | E11: =SUMIFS(Material_Purchase_Table[Revenue],Material_Purchase_Table[Project_ID],Project_Analysis!$A11) -> 53320700 | F11: =SUMIFS(Daily_Expenses_Table[Amount],Daily_Expenses_Table[Project_ID],Project_Analysis!$A11) -> 2127093 | G11: =SUMIFS(Equipment_Table[Fuel_Cost],Equipment_Table[Project_ID],Project_Analysis!$A11) -> 115793 | H11: =E11+F11+G11 -> 55563586 | I11: =C11-H11 -> 1.7443641e+08 | J11: =H11*100/C11 -> 24.158081 | K11: =IF(J11>100,"Critical",IF(AND(J11>=80,J11<=100),"Attention","Healthy")) -> Healthy | L11: =E11*100/H11 -> 95.963389 | M11: =F11*100/H11 -> 3.8282141 | N11: =G11*100/H11 -> 0.20839728 | O11: =IF(L11=MAX(L11,M11,N11),"Material",IF(M11=MAX(L11,M11,N11),"Daily Expense","Equipment")) -> Material
A12: P011 | B12: =INDEX(Project_Table[],MATCH(Project_Analysis!$A12,Project_Table[Project_ID],0),MATCH(Project_Analysis!B$1,Project_Table[#Headers],0)) -> SteelBuild Phase 11 | C12: =INDEX(Project_Table[],MATCH(Project_Analysis!$A12,Project_Table[Project_ID],0),MATCH(Project_Analysis!C$1,Project_Table[#Headers],0)) -> 140000000 | D12: =SUMIFS(Client_Payment_Table[Amount],Client_Payment_Table[Status],"Paid",Client_Payment_Table[Project_ID],Project_Analysis!$A12) -> 4850600 | E12: =SUMIFS(Material_Purchase_Table[Revenue],Material_Purchase_Table[Project_ID],Project_Analysis!$A12) -> 38558909 | F12: =SUMIFS(Daily_Expenses_Table[Amount],Daily_Expenses_Table[Project_ID],Project_Analysis!$A12) -> 1056564 | G12: =SUMIFS(Equipment_Table[Fuel_Cost],Equipment_Table[Project_ID],Project_Analysis!$A12) -> 227233 | H12: =E12+F12+G12 -> 39842706 | I12: =C12-H12 -> 1.0015729e+08 | J12: =H12*100/C12 -> 28.459076 | K12: =IF(J12>100,"Critical",IF(AND(J12>=80,J12<=100),"Attention","Healthy")) -> Healthy | L12: =E12*100/H12 -> 96.777837 | M12: =F12*100/H12 -> 2.6518379 | N12: =G12*100/H12 -> 0.57032521 | O12: =IF(L12=MAX(L12,M12,N12),"Material",IF(M12=MAX(L12,M12,N12),"Daily Expense","Equipment")) -> Material
A13: P012 | B13: =INDEX(Project_Table[],MATCH(Project_Analysis!$A13,Project_Table[Project_ID],0),MATCH(Project_Analysis!B$1,Project_Table[#Headers],0)) -> SteelBuild Phase 12 | C13: =INDEX(Project_Table[],MATCH(Project_Analysis!$A13,Project_Table[Project_ID],0),MATCH(Project_Analysis!C$1,Project_Table[#Headers],0)) -> 130000000 | D13: =SUMIFS(Client_Payment_Table[Amount],Client_Payment_Table[Status],"Paid",Client_Payment_Table[Project_ID],Project_Analysis!$A13) -> 9425946 | E13: =SUMIFS(Material_Purchase_Table[Revenue],Material_Purchase_Table[Project_ID],Project_Analysis!$A13) -> 39182880 | F13: =SUMIFS(Daily_Expenses_Table[Amount],Daily_Expenses_Table[Project_ID],Project_Analysis!$A13) -> 3233515 | G13: =SUMIFS(Equipment_Table[Fuel_Cost],Equipment_Table[Project_ID],Project_Analysis!$A13) -> 147777 | H13: =E13+F13+G13 -> 42564172 | I13: =C13-H13 -> 87435828 | J13: =H13*100/C13 -> 32.741671 | K13: =IF(J13>100,"Critical",IF(AND(J13>=80,J13<=100),"Attention","Healthy")) -> Healthy | L13: =E13*100/H13 -> 92.056014 | M13: =F13*100/H13 -> 7.5967999 | N13: =G13*100/H13 -> 0.34718636 | O13: =IF(L13=MAX(L13,M13,N13),"Material",IF(M13=MAX(L13,M13,N13),"Daily Expense","Equipment")) -> Material
A14: P013 | B14: =INDEX(Project_Table[],MATCH(Project_Analysis!$A14,Project_Table[Project_ID],0),MATCH(Project_Analysis!B$1,Project_Table[#Headers],0)) -> SteelBuild Phase 13 | C14: =INDEX(Project_Table[],MATCH(Project_Analysis!$A14,Project_Table[Project_ID],0),MATCH(Project_Analysis!C$1,Project_Table[#Headers],0)) -> 110000000 | D14: =SUMIFS(Client_Payment_Table[Amount],Client_Payment_Table[Status],"Paid",Client_Payment_Table[Project_ID],Project_Analysis!$A14) -> 0 | E14: =SUMIFS(Material_Purchase_Table[Revenue],Material_Purchase_Table[Project_ID],Project_Analysis!$A14) -> 50771592 | F14: =SUMIFS(Daily_Expenses_Table[Amount],Daily_Expenses_Table[Project_ID],Project_Analysis!$A14) -> 2112425 | G14: =SUMIFS(Equipment_Table[Fuel_Cost],Equipment_Table[Project_ID],Project_Analysis!$A14) -> 294914 | H14: =E14+F14+G14 -> 53178931 | I14: =C14-H14 -> 56821069 | J14: =H14*100/C14 -> 48.344482 | K14: =IF(J14>100,"Critical",IF(AND(J14>=80,J14<=100),"Attention","Healthy")) -> Healthy | L14: =E14*100/H14 -> 95.473134 | M14: =F14*100/H14 -> 3.9722969 | N14: =G14*100/H14 -> 0.55456926 | O14: =IF(L14=MAX(L14,M14,N14),"Material",IF(M14=MAX(L14,M14,N14),"Daily Expense","Equipment")) -> Material
... A151: P150 | B151: =INDEX(Project_Table[],MATCH(Project_Analysis!$A151,Project_Table[Project_ID],0),MATCH(Project_Analysis!B$1,Project_Table[#Headers],0)) -> SteelBuild Phase 150 | C151: =INDEX(Project_Table[],MATCH(Project_Analysis!$A151,Project_Table[Project_ID],0),MATCH(Project_Analysis!C$1,Project_Table[#Headers],0)) -> 220000000 | D151: =SUMIFS(Client_Payment_Table[Amount],Client_Payment_Table[Status],"Paid",Client_Payment_Table[Project_ID],Project_Analysis!$A151) -> 5914199 | E151: =SUMIFS(Material_Purchase_Table[Revenue],Material_Purchase_Table[Project_ID],Project_Analysis!$A151) -> 48986000 | F151: =SUMIFS(Daily_Expenses_Table[Amount],Daily_Expenses_Table[Project_ID],Project_Analysis!$A151) -> 1710062 | G151: =SUMIFS(Equipment_Table[Fuel_Cost],Equipment_Table[Project_ID],Project_Analysis!$A151) -> 298811 | H151: =E151+F151+G151 -> 50994873 | I151: =C151-H151 -> 1.6900513e+08 | J151: =H151*100/C151 -> 23.179488 | K151: =IF(J151>100,"Critical",IF(AND(J151>=80,J151<=100),"Attention","Healthy")) -> Healthy | L151: =E151*100/H151 -> 96.060637 | M151: =F151*100/H151 -> 3.3533998 | N151: =G151*100/H151 -> 0.58596282 | O151: =IF(L151=MAX(L151,M151,N151),"Material",IF(M151=MAX(L151,M151,N151),"Daily Expense","Equipment")) -> Material

Sheet Pivot_Analysis
A1: PROJECT FINANCIAL OVERVIEW
A2: Row Labels | B2: Budget | C2: Total_Actual_Cost
A3: P132 | B3: 70000000 | C3: 79164735
A4: P096 | B4: 350000000 | C4: 74880407
A5: P095 | B5: 240000000 | C5: 73740319
A6: P099 | B6: 80000000 | C6: 70460740
A7: P101 | B7: 300000000 | C7: 70134336
A8: P138 | B8: 130000000 | C8: 69714025
A9: P082 | B9: 130000000 | C9: 69218420
A10: P059 | B10: 360000000 | C10: 68779235
A11: P119 | B11: 370000000 | C11: 68564863
A12: P017 | B12: 290000000 | C12: 68453430
A13: P120 | B13: 120000000 | C13: 68337286
A14: P131 | B14: 380000000 | C14: 68164247
... A153: Grand Total | B153: 33240000000 | C153: 7.9133705e+09
A156: Project_Health | B156: (All)
A157: COST DRIVER ANALYSIS
A158: Row Labels | B158: Material Cost_% | C158: Daily Expenses_% | D158: Equipment Cost_%
A159: P001 | B159: 96.493463 | C159: 3.2783197 | D159: 0.22821722
A160: P002 | B160: 93.587784 | C160: 5.8323212 | D160: 0.57989478
A161: P003 | B161: 95.300901 | C161: 4.2308656 | D161: 0.46823379
A162: P004 | B162: 97.391441 | C162: 2.1593094 | D162: 0.44924948
A163: P005 | B163: 95.240175 | C163: 4.1519837 | D163: 0.6078409
A164: P006 | B164: 97.134466 | C164: 2.4729943 | D164: 0.39253974
A165: P007 | B165: 97.223828 | C165: 2.409549 | D165: 0.36662329
A166: P008 | B166: 95.033774 | C166: 4.5019613 | D166: 0.46426479
A167: P009 | B167: 96.199499 | C167: 3.3738344 | D167: 0.42666692
A168: P010 | B168: 95.963389 | C168: 3.8282141 | D168: 0.20839728
A169: P011 | B169: 96.777837 | C169: 2.6518379 | D169: 0.57032521
A170: P012 | B170: 92.056014 | C170: 7.5967999 | D170: 0.34718636
... A309: Grand Total | B309: 14337.821 | C309: 597.48214 | D309: 64.696504
A312: Project_Health | B312: (All)
A313: TOP 5 PROJECTS BY ACTUAL COST
A314: Row Labels | B314: Actual_Cost | C314: Budget
A315: P132 | B315: 79164735 | C315: 70000000
A316: P096 | B316: 74880407 | C316: 350000000
A317: P095 | B317: 73740319 | C317: 240000000
A318: P099 | B318: 70460740 | C318: 80000000
A319: P101 | B319: 70134336 | C319: 300000000
A320: Grand Total | B320: 3.6838054e+08 | C320: 1040000000
...

Sheet Dashboard
A1: STEELBUILD -- PROJECT PERFORMANCE DASHBOARD
A2: Project Cost, Budget Utilization & Health Analysis
C4: TOTAL PROJECTS | G4: TOTAL BUDGET | K4: ACTUAL COST | O4: BUDGET UTILIZATION | S4: CRITICAL PROJECTS | W4: ATTENTION PROJECTS
I9: PROJECT HEALTH
B13: TOP 5 BUDGET VS ACTUAL | L13: ACTUAL COST BY PROJECT HEALTH | V13: BUDGET UTILIZATION BY PROJECT HEALTH
A35: KEY MANAGEMENT INSIGHTS & ACTIONS
A36: 🔴 P132: 113.1% utilization; ~97% Material Cost → investigate material pricing, quantity and estimation.
A37: 🔴 P135: 102.3% utilization; ~97% Material Cost → review procurement and project estimate.
A38: 🟠 P099: 88.1% utilization → monitor remaining expenditure closely.
A39: 📊 Health: Utilization rises from 29% Healthy → 88% Attention → 108% Critical.
A40: 💡 Risk: High actual cost ≠ high risk; evaluate cost relative to approved budget.
